[I 241119 13:23:14 command:168] Visit me at http://0.0.0.0:5555
[I 241119 13:23:14 command:176] Broker: redis://localhost:6379/0
[I 241119 13:23:14 command:177] Registered tasks: 
    ['celery.accumulate',
     'celery.backend_cleanup',
     'celery.chain',
     'celery.chord',
     'celery.chord_unlock',
     'celery.chunks',
     'celery.group',
     'celery.map',
     'celery.starmap',
     'celery_worker.task.process_task',
     'celery_worker.task.run_user_automation']
[E 241119 13:23:20 events:191] Failed to capture events: 'Error 61 connecting to localhost:6379. Connection refused.', trying again in 2 seconds.
[E 241119 13:23:20 base_events:1858] Future exception was never retrieved
    future: <Future finished exception=OperationalError('Error 61 connecting to localhost:6379. Connection refused.')>
    Traceback (most recent call last):
      File "/Users/bibektimilsina/Library/Caches/pypoetry/virtualenvs/backend-yJOuBi-v-py3.13/lib/python3.13/site-packages/kombu/transport/virtual/base.py", line 951, in create_channel
        return self._avail_channels.pop()
               ~~~~~~~~~~~~~~~~~~~~~~~~^^
    IndexError: pop from empty list
    
    During handling of the above exception, another exception occurred:
    
    Traceback (most recent call last):
      File "/Users/bibektimilsina/Library/Caches/pypoetry/virtualenvs/backend-yJOuBi-v-py3.13/lib/python3.13/site-packages/redis/connection.py", line 357, in connect
        sock = self.retry.call_with_retry(
            lambda: self._connect(), lambda error: self.disconnect(error)
        )
      File "/Users/bibektimilsina/Library/Caches/pypoetry/virtualenvs/backend-yJOuBi-v-py3.13/lib/python3.13/site-packages/redis/retry.py", line 62, in call_with_retry
        return do()
      File "/Users/bibektimilsina/Library/Caches/pypoetry/virtualenvs/backend-yJOuBi-v-py3.13/lib/python3.13/site-packages/redis/connection.py", line 358, in <lambda>
        lambda: self._connect(), lambda error: self.disconnect(error)
                ~~~~~~~~~~~~~^^
      File "/Users/bibektimilsina/Library/Caches/pypoetry/virtualenvs/backend-yJOuBi-v-py3.13/lib/python3.13/site-packages/redis/connection.py", line 730, in _connect
        raise err
      File "/Users/bibektimilsina/Library/Caches/pypoetry/virtualenvs/backend-yJOuBi-v-py3.13/lib/python3.13/site-packages/redis/connection.py", line 718, in _connect
        sock.connect(socket_address)
        ~~~~~~~~~~~~^^^^^^^^^^^^^^^^
    ConnectionRefusedError: [Errno 61] Connection refused
    
    During handling of the above exception, another exception occurred:
    
    Traceback (most recent call last):
      File "/Users/bibektimilsina/Library/Caches/pypoetry/virtualenvs/backend-yJOuBi-v-py3.13/lib/python3.13/site-packages/kombu/connection.py", line 472, in _reraise_as_library_errors
        yield
      File "/Users/bibektimilsina/Library/Caches/pypoetry/virtualenvs/backend-yJOuBi-v-py3.13/lib/python3.13/site-packages/kombu/connection.py", line 459, in _ensure_connection
        return retry_over_time(
            self._connection_factory, self.recoverable_connection_errors,
        ...<2 lines>...
            callback, timeout=timeout
        )
      File "/Users/bibektimilsina/Library/Caches/pypoetry/virtualenvs/backend-yJOuBi-v-py3.13/lib/python3.13/site-packages/kombu/utils/functional.py", line 318, in retry_over_time
        return fun(*args, **kwargs)
      File "/Users/bibektimilsina/Library/Caches/pypoetry/virtualenvs/backend-yJOuBi-v-py3.13/lib/python3.13/site-packages/kombu/connection.py", line 934, in _connection_factory
        self._connection = self._establish_connection()
                           ~~~~~~~~~~~~~~~~~~~~~~~~~~^^
      File "/Users/bibektimilsina/Library/Caches/pypoetry/virtualenvs/backend-yJOuBi-v-py3.13/lib/python3.13/site-packages/kombu/connection.py", line 860, in _establish_connection
        conn = self.transport.establish_connection()
      File "/Users/bibektimilsina/Library/Caches/pypoetry/virtualenvs/backend-yJOuBi-v-py3.13/lib/python3.13/site-packages/kombu/transport/virtual/base.py", line 975, in establish_connection
        self._avail_channels.append(self.create_channel(self))
                                    ~~~~~~~~~~~~~~~~~~~^^^^^^
      File "/Users/bibektimilsina/Library/Caches/pypoetry/virtualenvs/backend-yJOuBi-v-py3.13/lib/python3.13/site-packages/kombu/transport/virtual/base.py", line 953, in create_channel
        channel = self.Channel(connection)
      File "/Users/bibektimilsina/Library/Caches/pypoetry/virtualenvs/backend-yJOuBi-v-py3.13/lib/python3.13/site-packages/kombu/transport/redis.py", line 744, in __init__
        self.client.ping()
        ~~~~~~~~~~~~~~~~^^
      File "/Users/bibektimilsina/Library/Caches/pypoetry/virtualenvs/backend-yJOuBi-v-py3.13/lib/python3.13/site-packages/redis/commands/core.py", line 1212, in ping
        return self.execute_command("PING", **kwargs)
               ~~~~~~~~~~~~~~~~~~~~^^^^^^^^^^^^^^^^^^
      File "/Users/bibektimilsina/Library/Caches/pypoetry/virtualenvs/backend-yJOuBi-v-py3.13/lib/python3.13/site-packages/redis/client.py", line 559, in execute_command
        return self._execute_command(*args, **options)
               ~~~~~~~~~~~~~~~~~~~~~^^^^^^^^^^^^^^^^^^
      File "/Users/bibektimilsina/Library/Caches/pypoetry/virtualenvs/backend-yJOuBi-v-py3.13/lib/python3.13/site-packages/redis/client.py", line 565, in _execute_command
        conn = self.connection or pool.get_connection(command_name, **options)
                                  ~~~~~~~~~~~~~~~~~~~^^^^^^^^^^^^^^^^^^^^^^^^^
      File "/Users/bibektimilsina/Library/Caches/pypoetry/virtualenvs/backend-yJOuBi-v-py3.13/lib/python3.13/site-packages/redis/connection.py", line 1422, in get_connection
        connection.connect()
        ~~~~~~~~~~~~~~~~~~^^
      File "/Users/bibektimilsina/Library/Caches/pypoetry/virtualenvs/backend-yJOuBi-v-py3.13/lib/python3.13/site-packages/redis/connection.py", line 363, in connect
        raise ConnectionError(self._error_message(e))
    redis.exceptions.ConnectionError: Error 61 connecting to localhost:6379. Connection refused.
    
    The above exception was the direct cause of the following exception:
    
    Traceback (most recent call last):
      File "/opt/homebrew/Cellar/python@3.13/3.13.0_1/Frameworks/Python.framework/Versions/3.13/lib/python3.13/concurrent/futures/thread.py", line 58, in run
        result = self.fn(*self.args, **self.kwargs)
      File "/Users/bibektimilsina/Library/Caches/pypoetry/virtualenvs/backend-yJOuBi-v-py3.13/lib/python3.13/site-packages/flower/inspector.py", line 37, in _inspect
        getattr(inspect, method)()
        ~~~~~~~~~~~~~~~~~~~~~~~~^^
      File "/Users/bibektimilsina/Library/Caches/pypoetry/virtualenvs/backend-yJOuBi-v-py3.13/lib/python3.13/site-packages/celery/app/control.py", line 338, in active_queues
        return self._request('active_queues')
               ~~~~~~~~~~~~~^^^^^^^^^^^^^^^^^
      File "/Users/bibektimilsina/Library/Caches/pypoetry/virtualenvs/backend-yJOuBi-v-py3.13/lib/python3.13/site-packages/celery/app/control.py", line 106, in _request
        return self._prepare(self.app.control.broadcast(
                             ~~~~~~~~~~~~~~~~~~~~~~~~~~^
            command,
            ^^^^^^^^
        ...<6 lines>...
            pattern=self.pattern, matcher=self.matcher,
            ^^^^^^^^^^^^^^^^^^^^^^^^^^^^^^^^^^^^^^^^^^^
        ))
        ^
      File "/Users/bibektimilsina/Library/Caches/pypoetry/virtualenvs/backend-yJOuBi-v-py3.13/lib/python3.13/site-packages/celery/app/control.py", line 776, in broadcast
        return self.mailbox(conn)._broadcast(
               ~~~~~~~~~~~~~~~~~~~~~~~~~~~~~^
            command, arguments, destination, reply, timeout,
            ^^^^^^^^^^^^^^^^^^^^^^^^^^^^^^^^^^^^^^^^^^^^^^^^
            limit, callback, channel=channel,
            ^^^^^^^^^^^^^^^^^^^^^^^^^^^^^^^^^
        )
        ^
      File "/Users/bibektimilsina/Library/Caches/pypoetry/virtualenvs/backend-yJOuBi-v-py3.13/lib/python3.13/site-packages/kombu/pidbox.py", line 330, in _broadcast
        chan = channel or self.connection.default_channel
                          ^^^^^^^^^^^^^^^^^^^^^^^^^^^^^^^
      File "/Users/bibektimilsina/Library/Caches/pypoetry/virtualenvs/backend-yJOuBi-v-py3.13/lib/python3.13/site-packages/kombu/connection.py", line 953, in default_channel
        self._ensure_connection(**conn_opts)
        ~~~~~~~~~~~~~~~~~~~~~~~^^^^^^^^^^^^^
      File "/Users/bibektimilsina/Library/Caches/pypoetry/virtualenvs/backend-yJOuBi-v-py3.13/lib/python3.13/site-packages/kombu/connection.py", line 458, in _ensure_connection
        with ctx():
             ~~~^^
      File "/opt/homebrew/Cellar/python@3.13/3.13.0_1/Frameworks/Python.framework/Versions/3.13/lib/python3.13/contextlib.py", line 162, in __exit__
        self.gen.throw(value)
        ~~~~~~~~~~~~~~^^^^^^^
      File "/Users/bibektimilsina/Library/Caches/pypoetry/virtualenvs/backend-yJOuBi-v-py3.13/lib/python3.13/site-packages/kombu/connection.py", line 476, in _reraise_as_library_errors
        raise ConnectionError(str(exc)) from exc
    kombu.exceptions.OperationalError: Error 61 connecting to localhost:6379. Connection refused.
[E 241119 13:23:20 base_events:1858] Future exception was never retrieved
    future: <Future finished exception=OperationalError('Error 61 connecting to localhost:6379. Connection refused.')>
    Traceback (most recent call last):
      File "/Users/bibektimilsina/Library/Caches/pypoetry/virtualenvs/backend-yJOuBi-v-py3.13/lib/python3.13/site-packages/kombu/transport/virtual/base.py", line 951, in create_channel
        return self._avail_channels.pop()
               ~~~~~~~~~~~~~~~~~~~~~~~~^^
    IndexError: pop from empty list
    
    During handling of the above exception, another exception occurred:
    
    Traceback (most recent call last):
      File "/Users/bibektimilsina/Library/Caches/pypoetry/virtualenvs/backend-yJOuBi-v-py3.13/lib/python3.13/site-packages/redis/connection.py", line 357, in connect
        sock = self.retry.call_with_retry(
            lambda: self._connect(), lambda error: self.disconnect(error)
        )
      File "/Users/bibektimilsina/Library/Caches/pypoetry/virtualenvs/backend-yJOuBi-v-py3.13/lib/python3.13/site-packages/redis/retry.py", line 62, in call_with_retry
        return do()
      File "/Users/bibektimilsina/Library/Caches/pypoetry/virtualenvs/backend-yJOuBi-v-py3.13/lib/python3.13/site-packages/redis/connection.py", line 358, in <lambda>
        lambda: self._connect(), lambda error: self.disconnect(error)
                ~~~~~~~~~~~~~^^
      File "/Users/bibektimilsina/Library/Caches/pypoetry/virtualenvs/backend-yJOuBi-v-py3.13/lib/python3.13/site-packages/redis/connection.py", line 730, in _connect
        raise err
      File "/Users/bibektimilsina/Library/Caches/pypoetry/virtualenvs/backend-yJOuBi-v-py3.13/lib/python3.13/site-packages/redis/connection.py", line 718, in _connect
        sock.connect(socket_address)
        ~~~~~~~~~~~~^^^^^^^^^^^^^^^^
    ConnectionRefusedError: [Errno 61] Connection refused
    
    During handling of the above exception, another exception occurred:
    
    Traceback (most recent call last):
      File "/Users/bibektimilsina/Library/Caches/pypoetry/virtualenvs/backend-yJOuBi-v-py3.13/lib/python3.13/site-packages/kombu/connection.py", line 472, in _reraise_as_library_errors
        yield
      File "/Users/bibektimilsina/Library/Caches/pypoetry/virtualenvs/backend-yJOuBi-v-py3.13/lib/python3.13/site-packages/kombu/connection.py", line 459, in _ensure_connection
        return retry_over_time(
            self._connection_factory, self.recoverable_connection_errors,
        ...<2 lines>...
            callback, timeout=timeout
        )
      File "/Users/bibektimilsina/Library/Caches/pypoetry/virtualenvs/backend-yJOuBi-v-py3.13/lib/python3.13/site-packages/kombu/utils/functional.py", line 318, in retry_over_time
        return fun(*args, **kwargs)
      File "/Users/bibektimilsina/Library/Caches/pypoetry/virtualenvs/backend-yJOuBi-v-py3.13/lib/python3.13/site-packages/kombu/connection.py", line 934, in _connection_factory
        self._connection = self._establish_connection()
                           ~~~~~~~~~~~~~~~~~~~~~~~~~~^^
      File "/Users/bibektimilsina/Library/Caches/pypoetry/virtualenvs/backend-yJOuBi-v-py3.13/lib/python3.13/site-packages/kombu/connection.py", line 860, in _establish_connection
        conn = self.transport.establish_connection()
      File "/Users/bibektimilsina/Library/Caches/pypoetry/virtualenvs/backend-yJOuBi-v-py3.13/lib/python3.13/site-packages/kombu/transport/virtual/base.py", line 975, in establish_connection
        self._avail_channels.append(self.create_channel(self))
                                    ~~~~~~~~~~~~~~~~~~~^^^^^^
      File "/Users/bibektimilsina/Library/Caches/pypoetry/virtualenvs/backend-yJOuBi-v-py3.13/lib/python3.13/site-packages/kombu/transport/virtual/base.py", line 953, in create_channel
        channel = self.Channel(connection)
      File "/Users/bibektimilsina/Library/Caches/pypoetry/virtualenvs/backend-yJOuBi-v-py3.13/lib/python3.13/site-packages/kombu/transport/redis.py", line 744, in __init__
        self.client.ping()
        ~~~~~~~~~~~~~~~~^^
      File "/Users/bibektimilsina/Library/Caches/pypoetry/virtualenvs/backend-yJOuBi-v-py3.13/lib/python3.13/site-packages/redis/commands/core.py", line 1212, in ping
        return self.execute_command("PING", **kwargs)
               ~~~~~~~~~~~~~~~~~~~~^^^^^^^^^^^^^^^^^^
      File "/Users/bibektimilsina/Library/Caches/pypoetry/virtualenvs/backend-yJOuBi-v-py3.13/lib/python3.13/site-packages/redis/client.py", line 559, in execute_command
        return self._execute_command(*args, **options)
               ~~~~~~~~~~~~~~~~~~~~~^^^^^^^^^^^^^^^^^^
      File "/Users/bibektimilsina/Library/Caches/pypoetry/virtualenvs/backend-yJOuBi-v-py3.13/lib/python3.13/site-packages/redis/client.py", line 565, in _execute_command
        conn = self.connection or pool.get_connection(command_name, **options)
                                  ~~~~~~~~~~~~~~~~~~~^^^^^^^^^^^^^^^^^^^^^^^^^
      File "/Users/bibektimilsina/Library/Caches/pypoetry/virtualenvs/backend-yJOuBi-v-py3.13/lib/python3.13/site-packages/redis/connection.py", line 1422, in get_connection
        connection.connect()
        ~~~~~~~~~~~~~~~~~~^^
      File "/Users/bibektimilsina/Library/Caches/pypoetry/virtualenvs/backend-yJOuBi-v-py3.13/lib/python3.13/site-packages/redis/connection.py", line 363, in connect
        raise ConnectionError(self._error_message(e))
    redis.exceptions.ConnectionError: Error 61 connecting to localhost:6379. Connection refused.
    
    The above exception was the direct cause of the following exception:
    
    Traceback (most recent call last):
      File "/opt/homebrew/Cellar/python@3.13/3.13.0_1/Frameworks/Python.framework/Versions/3.13/lib/python3.13/concurrent/futures/thread.py", line 58, in run
        result = self.fn(*self.args, **self.kwargs)
      File "/Users/bibektimilsina/Library/Caches/pypoetry/virtualenvs/backend-yJOuBi-v-py3.13/lib/python3.13/site-packages/flower/inspector.py", line 37, in _inspect
        getattr(inspect, method)()
        ~~~~~~~~~~~~~~~~~~~~~~~~^^
      File "/Users/bibektimilsina/Library/Caches/pypoetry/virtualenvs/backend-yJOuBi-v-py3.13/lib/python3.13/site-packages/celery/app/control.py", line 271, in registered
        return self._request('registered', taskinfoitems=taskinfoitems)
               ~~~~~~~~~~~~~^^^^^^^^^^^^^^^^^^^^^^^^^^^^^^^^^^^^^^^^^^^
      File "/Users/bibektimilsina/Library/Caches/pypoetry/virtualenvs/backend-yJOuBi-v-py3.13/lib/python3.13/site-packages/celery/app/control.py", line 106, in _request
        return self._prepare(self.app.control.broadcast(
                             ~~~~~~~~~~~~~~~~~~~~~~~~~~^
            command,
            ^^^^^^^^
        ...<6 lines>...
            pattern=self.pattern, matcher=self.matcher,
            ^^^^^^^^^^^^^^^^^^^^^^^^^^^^^^^^^^^^^^^^^^^
        ))
        ^
      File "/Users/bibektimilsina/Library/Caches/pypoetry/virtualenvs/backend-yJOuBi-v-py3.13/lib/python3.13/site-packages/celery/app/control.py", line 776, in broadcast
        return self.mailbox(conn)._broadcast(
               ~~~~~~~~~~~~~~~~~~~~~~~~~~~~~^
            command, arguments, destination, reply, timeout,
            ^^^^^^^^^^^^^^^^^^^^^^^^^^^^^^^^^^^^^^^^^^^^^^^^
            limit, callback, channel=channel,
            ^^^^^^^^^^^^^^^^^^^^^^^^^^^^^^^^^
        )
        ^
      File "/Users/bibektimilsina/Library/Caches/pypoetry/virtualenvs/backend-yJOuBi-v-py3.13/lib/python3.13/site-packages/kombu/pidbox.py", line 330, in _broadcast
        chan = channel or self.connection.default_channel
                          ^^^^^^^^^^^^^^^^^^^^^^^^^^^^^^^
      File "/Users/bibektimilsina/Library/Caches/pypoetry/virtualenvs/backend-yJOuBi-v-py3.13/lib/python3.13/site-packages/kombu/connection.py", line 953, in default_channel
        self._ensure_connection(**conn_opts)
        ~~~~~~~~~~~~~~~~~~~~~~~^^^^^^^^^^^^^
      File "/Users/bibektimilsina/Library/Caches/pypoetry/virtualenvs/backend-yJOuBi-v-py3.13/lib/python3.13/site-packages/kombu/connection.py", line 458, in _ensure_connection
        with ctx():
             ~~~^^
      File "/opt/homebrew/Cellar/python@3.13/3.13.0_1/Frameworks/Python.framework/Versions/3.13/lib/python3.13/contextlib.py", line 162, in __exit__
        self.gen.throw(value)
        ~~~~~~~~~~~~~~^^^^^^^
      File "/Users/bibektimilsina/Library/Caches/pypoetry/virtualenvs/backend-yJOuBi-v-py3.13/lib/python3.13/site-packages/kombu/connection.py", line 476, in _reraise_as_library_errors
        raise ConnectionError(str(exc)) from exc
    kombu.exceptions.OperationalError: Error 61 connecting to localhost:6379. Connection refused.
[E 241119 13:23:20 base_events:1858] Future exception was never retrieved
    future: <Future finished exception=OperationalError('Error 61 connecting to localhost:6379. Connection refused.')>
    Traceback (most recent call last):
      File "/Users/bibektimilsina/Library/Caches/pypoetry/virtualenvs/backend-yJOuBi-v-py3.13/lib/python3.13/site-packages/kombu/transport/virtual/base.py", line 951, in create_channel
        return self._avail_channels.pop()
               ~~~~~~~~~~~~~~~~~~~~~~~~^^
    IndexError: pop from empty list
    
    During handling of the above exception, another exception occurred:
    
    Traceback (most recent call last):
      File "/Users/bibektimilsina/Library/Caches/pypoetry/virtualenvs/backend-yJOuBi-v-py3.13/lib/python3.13/site-packages/redis/connection.py", line 357, in connect
        sock = self.retry.call_with_retry(
            lambda: self._connect(), lambda error: self.disconnect(error)
        )
      File "/Users/bibektimilsina/Library/Caches/pypoetry/virtualenvs/backend-yJOuBi-v-py3.13/lib/python3.13/site-packages/redis/retry.py", line 62, in call_with_retry
        return do()
      File "/Users/bibektimilsina/Library/Caches/pypoetry/virtualenvs/backend-yJOuBi-v-py3.13/lib/python3.13/site-packages/redis/connection.py", line 358, in <lambda>
        lambda: self._connect(), lambda error: self.disconnect(error)
                ~~~~~~~~~~~~~^^
      File "/Users/bibektimilsina/Library/Caches/pypoetry/virtualenvs/backend-yJOuBi-v-py3.13/lib/python3.13/site-packages/redis/connection.py", line 730, in _connect
        raise err
      File "/Users/bibektimilsina/Library/Caches/pypoetry/virtualenvs/backend-yJOuBi-v-py3.13/lib/python3.13/site-packages/redis/connection.py", line 718, in _connect
        sock.connect(socket_address)
        ~~~~~~~~~~~~^^^^^^^^^^^^^^^^
    ConnectionRefusedError: [Errno 61] Connection refused
    
    During handling of the above exception, another exception occurred:
    
    Traceback (most recent call last):
      File "/Users/bibektimilsina/Library/Caches/pypoetry/virtualenvs/backend-yJOuBi-v-py3.13/lib/python3.13/site-packages/kombu/connection.py", line 472, in _reraise_as_library_errors
        yield
      File "/Users/bibektimilsina/Library/Caches/pypoetry/virtualenvs/backend-yJOuBi-v-py3.13/lib/python3.13/site-packages/kombu/connection.py", line 459, in _ensure_connection
        return retry_over_time(
            self._connection_factory, self.recoverable_connection_errors,
        ...<2 lines>...
            callback, timeout=timeout
        )
      File "/Users/bibektimilsina/Library/Caches/pypoetry/virtualenvs/backend-yJOuBi-v-py3.13/lib/python3.13/site-packages/kombu/utils/functional.py", line 318, in retry_over_time
        return fun(*args, **kwargs)
      File "/Users/bibektimilsina/Library/Caches/pypoetry/virtualenvs/backend-yJOuBi-v-py3.13/lib/python3.13/site-packages/kombu/connection.py", line 934, in _connection_factory
        self._connection = self._establish_connection()
                           ~~~~~~~~~~~~~~~~~~~~~~~~~~^^
      File "/Users/bibektimilsina/Library/Caches/pypoetry/virtualenvs/backend-yJOuBi-v-py3.13/lib/python3.13/site-packages/kombu/connection.py", line 860, in _establish_connection
        conn = self.transport.establish_connection()
      File "/Users/bibektimilsina/Library/Caches/pypoetry/virtualenvs/backend-yJOuBi-v-py3.13/lib/python3.13/site-packages/kombu/transport/virtual/base.py", line 975, in establish_connection
        self._avail_channels.append(self.create_channel(self))
                                    ~~~~~~~~~~~~~~~~~~~^^^^^^
      File "/Users/bibektimilsina/Library/Caches/pypoetry/virtualenvs/backend-yJOuBi-v-py3.13/lib/python3.13/site-packages/kombu/transport/virtual/base.py", line 953, in create_channel
        channel = self.Channel(connection)
      File "/Users/bibektimilsina/Library/Caches/pypoetry/virtualenvs/backend-yJOuBi-v-py3.13/lib/python3.13/site-packages/kombu/transport/redis.py", line 744, in __init__
        self.client.ping()
        ~~~~~~~~~~~~~~~~^^
      File "/Users/bibektimilsina/Library/Caches/pypoetry/virtualenvs/backend-yJOuBi-v-py3.13/lib/python3.13/site-packages/redis/commands/core.py", line 1212, in ping
        return self.execute_command("PING", **kwargs)
               ~~~~~~~~~~~~~~~~~~~~^^^^^^^^^^^^^^^^^^
      File "/Users/bibektimilsina/Library/Caches/pypoetry/virtualenvs/backend-yJOuBi-v-py3.13/lib/python3.13/site-packages/redis/client.py", line 559, in execute_command
        return self._execute_command(*args, **options)
               ~~~~~~~~~~~~~~~~~~~~~^^^^^^^^^^^^^^^^^^
      File "/Users/bibektimilsina/Library/Caches/pypoetry/virtualenvs/backend-yJOuBi-v-py3.13/lib/python3.13/site-packages/redis/client.py", line 565, in _execute_command
        conn = self.connection or pool.get_connection(command_name, **options)
                                  ~~~~~~~~~~~~~~~~~~~^^^^^^^^^^^^^^^^^^^^^^^^^
      File "/Users/bibektimilsina/Library/Caches/pypoetry/virtualenvs/backend-yJOuBi-v-py3.13/lib/python3.13/site-packages/redis/connection.py", line 1422, in get_connection
        connection.connect()
        ~~~~~~~~~~~~~~~~~~^^
      File "/Users/bibektimilsina/Library/Caches/pypoetry/virtualenvs/backend-yJOuBi-v-py3.13/lib/python3.13/site-packages/redis/connection.py", line 363, in connect
        raise ConnectionError(self._error_message(e))
    redis.exceptions.ConnectionError: Error 61 connecting to localhost:6379. Connection refused.
    
    The above exception was the direct cause of the following exception:
    
    Traceback (most recent call last):
      File "/opt/homebrew/Cellar/python@3.13/3.13.0_1/Frameworks/Python.framework/Versions/3.13/lib/python3.13/concurrent/futures/thread.py", line 58, in run
        result = self.fn(*self.args, **self.kwargs)
      File "/Users/bibektimilsina/Library/Caches/pypoetry/virtualenvs/backend-yJOuBi-v-py3.13/lib/python3.13/site-packages/flower/inspector.py", line 37, in _inspect
        getattr(inspect, method)()
        ~~~~~~~~~~~~~~~~~~~~~~~~^^
      File "/Users/bibektimilsina/Library/Caches/pypoetry/virtualenvs/backend-yJOuBi-v-py3.13/lib/python3.13/site-packages/celery/app/control.py", line 243, in stats
        return self._request('stats')
               ~~~~~~~~~~~~~^^^^^^^^^
      File "/Users/bibektimilsina/Library/Caches/pypoetry/virtualenvs/backend-yJOuBi-v-py3.13/lib/python3.13/site-packages/celery/app/control.py", line 106, in _request
        return self._prepare(self.app.control.broadcast(
                             ~~~~~~~~~~~~~~~~~~~~~~~~~~^
            command,
            ^^^^^^^^
        ...<6 lines>...
            pattern=self.pattern, matcher=self.matcher,
            ^^^^^^^^^^^^^^^^^^^^^^^^^^^^^^^^^^^^^^^^^^^
        ))
        ^
      File "/Users/bibektimilsina/Library/Caches/pypoetry/virtualenvs/backend-yJOuBi-v-py3.13/lib/python3.13/site-packages/celery/app/control.py", line 776, in broadcast
        return self.mailbox(conn)._broadcast(
               ~~~~~~~~~~~~~~~~~~~~~~~~~~~~~^
            command, arguments, destination, reply, timeout,
            ^^^^^^^^^^^^^^^^^^^^^^^^^^^^^^^^^^^^^^^^^^^^^^^^
            limit, callback, channel=channel,
            ^^^^^^^^^^^^^^^^^^^^^^^^^^^^^^^^^
        )
        ^
      File "/Users/bibektimilsina/Library/Caches/pypoetry/virtualenvs/backend-yJOuBi-v-py3.13/lib/python3.13/site-packages/kombu/pidbox.py", line 330, in _broadcast
        chan = channel or self.connection.default_channel
                          ^^^^^^^^^^^^^^^^^^^^^^^^^^^^^^^
      File "/Users/bibektimilsina/Library/Caches/pypoetry/virtualenvs/backend-yJOuBi-v-py3.13/lib/python3.13/site-packages/kombu/connection.py", line 953, in default_channel
        self._ensure_connection(**conn_opts)
        ~~~~~~~~~~~~~~~~~~~~~~~^^^^^^^^^^^^^
      File "/Users/bibektimilsina/Library/Caches/pypoetry/virtualenvs/backend-yJOuBi-v-py3.13/lib/python3.13/site-packages/kombu/connection.py", line 458, in _ensure_connection
        with ctx():
             ~~~^^
      File "/opt/homebrew/Cellar/python@3.13/3.13.0_1/Frameworks/Python.framework/Versions/3.13/lib/python3.13/contextlib.py", line 162, in __exit__
        self.gen.throw(value)
        ~~~~~~~~~~~~~~^^^^^^^
      File "/Users/bibektimilsina/Library/Caches/pypoetry/virtualenvs/backend-yJOuBi-v-py3.13/lib/python3.13/site-packages/kombu/connection.py", line 476, in _reraise_as_library_errors
        raise ConnectionError(str(exc)) from exc
    kombu.exceptions.OperationalError: Error 61 connecting to localhost:6379. Connection refused.
[E 241119 13:23:20 base_events:1858] Future exception was never retrieved
    future: <Future finished exception=OperationalError('Error 61 connecting to localhost:6379. Connection refused.')>
    Traceback (most recent call last):
      File "/Users/bibektimilsina/Library/Caches/pypoetry/virtualenvs/backend-yJOuBi-v-py3.13/lib/python3.13/site-packages/kombu/transport/virtual/base.py", line 951, in create_channel
        return self._avail_channels.pop()
               ~~~~~~~~~~~~~~~~~~~~~~~~^^
    IndexError: pop from empty list
    
    During handling of the above exception, another exception occurred:
    
    Traceback (most recent call last):
      File "/Users/bibektimilsina/Library/Caches/pypoetry/virtualenvs/backend-yJOuBi-v-py3.13/lib/python3.13/site-packages/redis/connection.py", line 357, in connect
        sock = self.retry.call_with_retry(
            lambda: self._connect(), lambda error: self.disconnect(error)
        )
      File "/Users/bibektimilsina/Library/Caches/pypoetry/virtualenvs/backend-yJOuBi-v-py3.13/lib/python3.13/site-packages/redis/retry.py", line 62, in call_with_retry
        return do()
      File "/Users/bibektimilsina/Library/Caches/pypoetry/virtualenvs/backend-yJOuBi-v-py3.13/lib/python3.13/site-packages/redis/connection.py", line 358, in <lambda>
        lambda: self._connect(), lambda error: self.disconnect(error)
                ~~~~~~~~~~~~~^^
      File "/Users/bibektimilsina/Library/Caches/pypoetry/virtualenvs/backend-yJOuBi-v-py3.13/lib/python3.13/site-packages/redis/connection.py", line 730, in _connect
        raise err
      File "/Users/bibektimilsina/Library/Caches/pypoetry/virtualenvs/backend-yJOuBi-v-py3.13/lib/python3.13/site-packages/redis/connection.py", line 718, in _connect
        sock.connect(socket_address)
        ~~~~~~~~~~~~^^^^^^^^^^^^^^^^
    ConnectionRefusedError: [Errno 61] Connection refused
    
    During handling of the above exception, another exception occurred:
    
    Traceback (most recent call last):
      File "/Users/bibektimilsina/Library/Caches/pypoetry/virtualenvs/backend-yJOuBi-v-py3.13/lib/python3.13/site-packages/kombu/connection.py", line 472, in _reraise_as_library_errors
        yield
      File "/Users/bibektimilsina/Library/Caches/pypoetry/virtualenvs/backend-yJOuBi-v-py3.13/lib/python3.13/site-packages/kombu/connection.py", line 459, in _ensure_connection
        return retry_over_time(
            self._connection_factory, self.recoverable_connection_errors,
        ...<2 lines>...
            callback, timeout=timeout
        )
      File "/Users/bibektimilsina/Library/Caches/pypoetry/virtualenvs/backend-yJOuBi-v-py3.13/lib/python3.13/site-packages/kombu/utils/functional.py", line 318, in retry_over_time
        return fun(*args, **kwargs)
      File "/Users/bibektimilsina/Library/Caches/pypoetry/virtualenvs/backend-yJOuBi-v-py3.13/lib/python3.13/site-packages/kombu/connection.py", line 934, in _connection_factory
        self._connection = self._establish_connection()
                           ~~~~~~~~~~~~~~~~~~~~~~~~~~^^
      File "/Users/bibektimilsina/Library/Caches/pypoetry/virtualenvs/backend-yJOuBi-v-py3.13/lib/python3.13/site-packages/kombu/connection.py", line 860, in _establish_connection
        conn = self.transport.establish_connection()
      File "/Users/bibektimilsina/Library/Caches/pypoetry/virtualenvs/backend-yJOuBi-v-py3.13/lib/python3.13/site-packages/kombu/transport/virtual/base.py", line 975, in establish_connection
        self._avail_channels.append(self.create_channel(self))
                                    ~~~~~~~~~~~~~~~~~~~^^^^^^
      File "/Users/bibektimilsina/Library/Caches/pypoetry/virtualenvs/backend-yJOuBi-v-py3.13/lib/python3.13/site-packages/kombu/transport/virtual/base.py", line 953, in create_channel
        channel = self.Channel(connection)
      File "/Users/bibektimilsina/Library/Caches/pypoetry/virtualenvs/backend-yJOuBi-v-py3.13/lib/python3.13/site-packages/kombu/transport/redis.py", line 744, in __init__
        self.client.ping()
        ~~~~~~~~~~~~~~~~^^
      File "/Users/bibektimilsina/Library/Caches/pypoetry/virtualenvs/backend-yJOuBi-v-py3.13/lib/python3.13/site-packages/redis/commands/core.py", line 1212, in ping
        return self.execute_command("PING", **kwargs)
               ~~~~~~~~~~~~~~~~~~~~^^^^^^^^^^^^^^^^^^
      File "/Users/bibektimilsina/Library/Caches/pypoetry/virtualenvs/backend-yJOuBi-v-py3.13/lib/python3.13/site-packages/redis/client.py", line 559, in execute_command
        return self._execute_command(*args, **options)
               ~~~~~~~~~~~~~~~~~~~~~^^^^^^^^^^^^^^^^^^
      File "/Users/bibektimilsina/Library/Caches/pypoetry/virtualenvs/backend-yJOuBi-v-py3.13/lib/python3.13/site-packages/redis/client.py", line 565, in _execute_command
        conn = self.connection or pool.get_connection(command_name, **options)
                                  ~~~~~~~~~~~~~~~~~~~^^^^^^^^^^^^^^^^^^^^^^^^^
      File "/Users/bibektimilsina/Library/Caches/pypoetry/virtualenvs/backend-yJOuBi-v-py3.13/lib/python3.13/site-packages/redis/connection.py", line 1422, in get_connection
        connection.connect()
        ~~~~~~~~~~~~~~~~~~^^
      File "/Users/bibektimilsina/Library/Caches/pypoetry/virtualenvs/backend-yJOuBi-v-py3.13/lib/python3.13/site-packages/redis/connection.py", line 363, in connect
        raise ConnectionError(self._error_message(e))
    redis.exceptions.ConnectionError: Error 61 connecting to localhost:6379. Connection refused.
    
    The above exception was the direct cause of the following exception:
    
    Traceback (most recent call last):
      File "/opt/homebrew/Cellar/python@3.13/3.13.0_1/Frameworks/Python.framework/Versions/3.13/lib/python3.13/concurrent/futures/thread.py", line 58, in run
        result = self.fn(*self.args, **self.kwargs)
      File "/Users/bibektimilsina/Library/Caches/pypoetry/virtualenvs/backend-yJOuBi-v-py3.13/lib/python3.13/site-packages/flower/inspector.py", line 37, in _inspect
        getattr(inspect, method)()
        ~~~~~~~~~~~~~~~~~~~~~~~~^^
      File "/Users/bibektimilsina/Library/Caches/pypoetry/virtualenvs/backend-yJOuBi-v-py3.13/lib/python3.13/site-packages/celery/app/control.py", line 254, in revoked
        return self._request('revoked')
               ~~~~~~~~~~~~~^^^^^^^^^^^
      File "/Users/bibektimilsina/Library/Caches/pypoetry/virtualenvs/backend-yJOuBi-v-py3.13/lib/python3.13/site-packages/celery/app/control.py", line 106, in _request
        return self._prepare(self.app.control.broadcast(
                             ~~~~~~~~~~~~~~~~~~~~~~~~~~^
            command,
            ^^^^^^^^
        ...<6 lines>...
            pattern=self.pattern, matcher=self.matcher,
            ^^^^^^^^^^^^^^^^^^^^^^^^^^^^^^^^^^^^^^^^^^^
        ))
        ^
      File "/Users/bibektimilsina/Library/Caches/pypoetry/virtualenvs/backend-yJOuBi-v-py3.13/lib/python3.13/site-packages/celery/app/control.py", line 776, in broadcast
        return self.mailbox(conn)._broadcast(
               ~~~~~~~~~~~~~~~~~~~~~~~~~~~~~^
            command, arguments, destination, reply, timeout,
            ^^^^^^^^^^^^^^^^^^^^^^^^^^^^^^^^^^^^^^^^^^^^^^^^
            limit, callback, channel=channel,
            ^^^^^^^^^^^^^^^^^^^^^^^^^^^^^^^^^
        )
        ^
      File "/Users/bibektimilsina/Library/Caches/pypoetry/virtualenvs/backend-yJOuBi-v-py3.13/lib/python3.13/site-packages/kombu/pidbox.py", line 330, in _broadcast
        chan = channel or self.connection.default_channel
                          ^^^^^^^^^^^^^^^^^^^^^^^^^^^^^^^
      File "/Users/bibektimilsina/Library/Caches/pypoetry/virtualenvs/backend-yJOuBi-v-py3.13/lib/python3.13/site-packages/kombu/connection.py", line 953, in default_channel
        self._ensure_connection(**conn_opts)
        ~~~~~~~~~~~~~~~~~~~~~~~^^^^^^^^^^^^^
      File "/Users/bibektimilsina/Library/Caches/pypoetry/virtualenvs/backend-yJOuBi-v-py3.13/lib/python3.13/site-packages/kombu/connection.py", line 458, in _ensure_connection
        with ctx():
             ~~~^^
      File "/opt/homebrew/Cellar/python@3.13/3.13.0_1/Frameworks/Python.framework/Versions/3.13/lib/python3.13/contextlib.py", line 162, in __exit__
        self.gen.throw(value)
        ~~~~~~~~~~~~~~^^^^^^^
      File "/Users/bibektimilsina/Library/Caches/pypoetry/virtualenvs/backend-yJOuBi-v-py3.13/lib/python3.13/site-packages/kombu/connection.py", line 476, in _reraise_as_library_errors
        raise ConnectionError(str(exc)) from exc
    kombu.exceptions.OperationalError: Error 61 connecting to localhost:6379. Connection refused.
[E 241119 13:23:20 base_events:1858] Future exception was never retrieved
    future: <Future finished exception=OperationalError('Error 61 connecting to localhost:6379. Connection refused.')>
    Traceback (most recent call last):
      File "/Users/bibektimilsina/Library/Caches/pypoetry/virtualenvs/backend-yJOuBi-v-py3.13/lib/python3.13/site-packages/kombu/transport/virtual/base.py", line 951, in create_channel
        return self._avail_channels.pop()
               ~~~~~~~~~~~~~~~~~~~~~~~~^^
    IndexError: pop from empty list
    
    During handling of the above exception, another exception occurred:
    
    Traceback (most recent call last):
      File "/Users/bibektimilsina/Library/Caches/pypoetry/virtualenvs/backend-yJOuBi-v-py3.13/lib/python3.13/site-packages/redis/connection.py", line 357, in connect
        sock = self.retry.call_with_retry(
            lambda: self._connect(), lambda error: self.disconnect(error)
        )
      File "/Users/bibektimilsina/Library/Caches/pypoetry/virtualenvs/backend-yJOuBi-v-py3.13/lib/python3.13/site-packages/redis/retry.py", line 62, in call_with_retry
        return do()
      File "/Users/bibektimilsina/Library/Caches/pypoetry/virtualenvs/backend-yJOuBi-v-py3.13/lib/python3.13/site-packages/redis/connection.py", line 358, in <lambda>
        lambda: self._connect(), lambda error: self.disconnect(error)
                ~~~~~~~~~~~~~^^
      File "/Users/bibektimilsina/Library/Caches/pypoetry/virtualenvs/backend-yJOuBi-v-py3.13/lib/python3.13/site-packages/redis/connection.py", line 730, in _connect
        raise err
      File "/Users/bibektimilsina/Library/Caches/pypoetry/virtualenvs/backend-yJOuBi-v-py3.13/lib/python3.13/site-packages/redis/connection.py", line 718, in _connect
        sock.connect(socket_address)
        ~~~~~~~~~~~~^^^^^^^^^^^^^^^^
    ConnectionRefusedError: [Errno 61] Connection refused
    
    During handling of the above exception, another exception occurred:
    
    Traceback (most recent call last):
      File "/Users/bibektimilsina/Library/Caches/pypoetry/virtualenvs/backend-yJOuBi-v-py3.13/lib/python3.13/site-packages/kombu/connection.py", line 472, in _reraise_as_library_errors
        yield
      File "/Users/bibektimilsina/Library/Caches/pypoetry/virtualenvs/backend-yJOuBi-v-py3.13/lib/python3.13/site-packages/kombu/connection.py", line 459, in _ensure_connection
        return retry_over_time(
            self._connection_factory, self.recoverable_connection_errors,
        ...<2 lines>...
            callback, timeout=timeout
        )
      File "/Users/bibektimilsina/Library/Caches/pypoetry/virtualenvs/backend-yJOuBi-v-py3.13/lib/python3.13/site-packages/kombu/utils/functional.py", line 318, in retry_over_time
        return fun(*args, **kwargs)
      File "/Users/bibektimilsina/Library/Caches/pypoetry/virtualenvs/backend-yJOuBi-v-py3.13/lib/python3.13/site-packages/kombu/connection.py", line 934, in _connection_factory
        self._connection = self._establish_connection()
                           ~~~~~~~~~~~~~~~~~~~~~~~~~~^^
      File "/Users/bibektimilsina/Library/Caches/pypoetry/virtualenvs/backend-yJOuBi-v-py3.13/lib/python3.13/site-packages/kombu/connection.py", line 860, in _establish_connection
        conn = self.transport.establish_connection()
      File "/Users/bibektimilsina/Library/Caches/pypoetry/virtualenvs/backend-yJOuBi-v-py3.13/lib/python3.13/site-packages/kombu/transport/virtual/base.py", line 975, in establish_connection
        self._avail_channels.append(self.create_channel(self))
                                    ~~~~~~~~~~~~~~~~~~~^^^^^^
      File "/Users/bibektimilsina/Library/Caches/pypoetry/virtualenvs/backend-yJOuBi-v-py3.13/lib/python3.13/site-packages/kombu/transport/virtual/base.py", line 953, in create_channel
        channel = self.Channel(connection)
      File "/Users/bibektimilsina/Library/Caches/pypoetry/virtualenvs/backend-yJOuBi-v-py3.13/lib/python3.13/site-packages/kombu/transport/redis.py", line 744, in __init__
        self.client.ping()
        ~~~~~~~~~~~~~~~~^^
      File "/Users/bibektimilsina/Library/Caches/pypoetry/virtualenvs/backend-yJOuBi-v-py3.13/lib/python3.13/site-packages/redis/commands/core.py", line 1212, in ping
        return self.execute_command("PING", **kwargs)
               ~~~~~~~~~~~~~~~~~~~~^^^^^^^^^^^^^^^^^^
      File "/Users/bibektimilsina/Library/Caches/pypoetry/virtualenvs/backend-yJOuBi-v-py3.13/lib/python3.13/site-packages/redis/client.py", line 559, in execute_command
        return self._execute_command(*args, **options)
               ~~~~~~~~~~~~~~~~~~~~~^^^^^^^^^^^^^^^^^^
      File "/Users/bibektimilsina/Library/Caches/pypoetry/virtualenvs/backend-yJOuBi-v-py3.13/lib/python3.13/site-packages/redis/client.py", line 565, in _execute_command
        conn = self.connection or pool.get_connection(command_name, **options)
                                  ~~~~~~~~~~~~~~~~~~~^^^^^^^^^^^^^^^^^^^^^^^^^
      File "/Users/bibektimilsina/Library/Caches/pypoetry/virtualenvs/backend-yJOuBi-v-py3.13/lib/python3.13/site-packages/redis/connection.py", line 1422, in get_connection
        connection.connect()
        ~~~~~~~~~~~~~~~~~~^^
      File "/Users/bibektimilsina/Library/Caches/pypoetry/virtualenvs/backend-yJOuBi-v-py3.13/lib/python3.13/site-packages/redis/connection.py", line 363, in connect
        raise ConnectionError(self._error_message(e))
    redis.exceptions.ConnectionError: Error 61 connecting to localhost:6379. Connection refused.
    
    The above exception was the direct cause of the following exception:
    
    Traceback (most recent call last):
      File "/opt/homebrew/Cellar/python@3.13/3.13.0_1/Frameworks/Python.framework/Versions/3.13/lib/python3.13/concurrent/futures/thread.py", line 58, in run
        result = self.fn(*self.args, **self.kwargs)
      File "/Users/bibektimilsina/Library/Caches/pypoetry/virtualenvs/backend-yJOuBi-v-py3.13/lib/python3.13/site-packages/flower/inspector.py", line 37, in _inspect
        getattr(inspect, method)()
        ~~~~~~~~~~~~~~~~~~~~~~~~^^
      File "/Users/bibektimilsina/Library/Caches/pypoetry/virtualenvs/backend-yJOuBi-v-py3.13/lib/python3.13/site-packages/celery/app/control.py", line 166, in scheduled
        return self._request('scheduled')
               ~~~~~~~~~~~~~^^^^^^^^^^^^^
      File "/Users/bibektimilsina/Library/Caches/pypoetry/virtualenvs/backend-yJOuBi-v-py3.13/lib/python3.13/site-packages/celery/app/control.py", line 106, in _request
        return self._prepare(self.app.control.broadcast(
                             ~~~~~~~~~~~~~~~~~~~~~~~~~~^
            command,
            ^^^^^^^^
        ...<6 lines>...
            pattern=self.pattern, matcher=self.matcher,
            ^^^^^^^^^^^^^^^^^^^^^^^^^^^^^^^^^^^^^^^^^^^
        ))
        ^
      File "/Users/bibektimilsina/Library/Caches/pypoetry/virtualenvs/backend-yJOuBi-v-py3.13/lib/python3.13/site-packages/celery/app/control.py", line 776, in broadcast
        return self.mailbox(conn)._broadcast(
               ~~~~~~~~~~~~~~~~~~~~~~~~~~~~~^
            command, arguments, destination, reply, timeout,
            ^^^^^^^^^^^^^^^^^^^^^^^^^^^^^^^^^^^^^^^^^^^^^^^^
            limit, callback, channel=channel,
            ^^^^^^^^^^^^^^^^^^^^^^^^^^^^^^^^^
        )
        ^
      File "/Users/bibektimilsina/Library/Caches/pypoetry/virtualenvs/backend-yJOuBi-v-py3.13/lib/python3.13/site-packages/kombu/pidbox.py", line 330, in _broadcast
        chan = channel or self.connection.default_channel
                          ^^^^^^^^^^^^^^^^^^^^^^^^^^^^^^^
      File "/Users/bibektimilsina/Library/Caches/pypoetry/virtualenvs/backend-yJOuBi-v-py3.13/lib/python3.13/site-packages/kombu/connection.py", line 953, in default_channel
        self._ensure_connection(**conn_opts)
        ~~~~~~~~~~~~~~~~~~~~~~~^^^^^^^^^^^^^
      File "/Users/bibektimilsina/Library/Caches/pypoetry/virtualenvs/backend-yJOuBi-v-py3.13/lib/python3.13/site-packages/kombu/connection.py", line 458, in _ensure_connection
        with ctx():
             ~~~^^
      File "/opt/homebrew/Cellar/python@3.13/3.13.0_1/Frameworks/Python.framework/Versions/3.13/lib/python3.13/contextlib.py", line 162, in __exit__
        self.gen.throw(value)
        ~~~~~~~~~~~~~~^^^^^^^
      File "/Users/bibektimilsina/Library/Caches/pypoetry/virtualenvs/backend-yJOuBi-v-py3.13/lib/python3.13/site-packages/kombu/connection.py", line 476, in _reraise_as_library_errors
        raise ConnectionError(str(exc)) from exc
    kombu.exceptions.OperationalError: Error 61 connecting to localhost:6379. Connection refused.
[E 241119 13:23:20 base_events:1858] Future exception was never retrieved
    future: <Future finished exception=OperationalError('Error 61 connecting to localhost:6379. Connection refused.')>
    Traceback (most recent call last):
      File "/Users/bibektimilsina/Library/Caches/pypoetry/virtualenvs/backend-yJOuBi-v-py3.13/lib/python3.13/site-packages/kombu/transport/virtual/base.py", line 951, in create_channel
        return self._avail_channels.pop()
               ~~~~~~~~~~~~~~~~~~~~~~~~^^
    IndexError: pop from empty list
    
    During handling of the above exception, another exception occurred:
    
    Traceback (most recent call last):
      File "/Users/bibektimilsina/Library/Caches/pypoetry/virtualenvs/backend-yJOuBi-v-py3.13/lib/python3.13/site-packages/redis/connection.py", line 357, in connect
        sock = self.retry.call_with_retry(
            lambda: self._connect(), lambda error: self.disconnect(error)
        )
      File "/Users/bibektimilsina/Library/Caches/pypoetry/virtualenvs/backend-yJOuBi-v-py3.13/lib/python3.13/site-packages/redis/retry.py", line 62, in call_with_retry
        return do()
      File "/Users/bibektimilsina/Library/Caches/pypoetry/virtualenvs/backend-yJOuBi-v-py3.13/lib/python3.13/site-packages/redis/connection.py", line 358, in <lambda>
        lambda: self._connect(), lambda error: self.disconnect(error)
                ~~~~~~~~~~~~~^^
      File "/Users/bibektimilsina/Library/Caches/pypoetry/virtualenvs/backend-yJOuBi-v-py3.13/lib/python3.13/site-packages/redis/connection.py", line 730, in _connect
        raise err
      File "/Users/bibektimilsina/Library/Caches/pypoetry/virtualenvs/backend-yJOuBi-v-py3.13/lib/python3.13/site-packages/redis/connection.py", line 718, in _connect
        sock.connect(socket_address)
        ~~~~~~~~~~~~^^^^^^^^^^^^^^^^
    ConnectionRefusedError: [Errno 61] Connection refused
    
    During handling of the above exception, another exception occurred:
    
    Traceback (most recent call last):
      File "/Users/bibektimilsina/Library/Caches/pypoetry/virtualenvs/backend-yJOuBi-v-py3.13/lib/python3.13/site-packages/kombu/connection.py", line 472, in _reraise_as_library_errors
        yield
      File "/Users/bibektimilsina/Library/Caches/pypoetry/virtualenvs/backend-yJOuBi-v-py3.13/lib/python3.13/site-packages/kombu/connection.py", line 459, in _ensure_connection
        return retry_over_time(
            self._connection_factory, self.recoverable_connection_errors,
        ...<2 lines>...
            callback, timeout=timeout
        )
      File "/Users/bibektimilsina/Library/Caches/pypoetry/virtualenvs/backend-yJOuBi-v-py3.13/lib/python3.13/site-packages/kombu/utils/functional.py", line 318, in retry_over_time
        return fun(*args, **kwargs)
      File "/Users/bibektimilsina/Library/Caches/pypoetry/virtualenvs/backend-yJOuBi-v-py3.13/lib/python3.13/site-packages/kombu/connection.py", line 934, in _connection_factory
        self._connection = self._establish_connection()
                           ~~~~~~~~~~~~~~~~~~~~~~~~~~^^
      File "/Users/bibektimilsina/Library/Caches/pypoetry/virtualenvs/backend-yJOuBi-v-py3.13/lib/python3.13/site-packages/kombu/connection.py", line 860, in _establish_connection
        conn = self.transport.establish_connection()
      File "/Users/bibektimilsina/Library/Caches/pypoetry/virtualenvs/backend-yJOuBi-v-py3.13/lib/python3.13/site-packages/kombu/transport/virtual/base.py", line 975, in establish_connection
        self._avail_channels.append(self.create_channel(self))
                                    ~~~~~~~~~~~~~~~~~~~^^^^^^
      File "/Users/bibektimilsina/Library/Caches/pypoetry/virtualenvs/backend-yJOuBi-v-py3.13/lib/python3.13/site-packages/kombu/transport/virtual/base.py", line 953, in create_channel
        channel = self.Channel(connection)
      File "/Users/bibektimilsina/Library/Caches/pypoetry/virtualenvs/backend-yJOuBi-v-py3.13/lib/python3.13/site-packages/kombu/transport/redis.py", line 744, in __init__
        self.client.ping()
        ~~~~~~~~~~~~~~~~^^
      File "/Users/bibektimilsina/Library/Caches/pypoetry/virtualenvs/backend-yJOuBi-v-py3.13/lib/python3.13/site-packages/redis/commands/core.py", line 1212, in ping
        return self.execute_command("PING", **kwargs)
               ~~~~~~~~~~~~~~~~~~~~^^^^^^^^^^^^^^^^^^
      File "/Users/bibektimilsina/Library/Caches/pypoetry/virtualenvs/backend-yJOuBi-v-py3.13/lib/python3.13/site-packages/redis/client.py", line 559, in execute_command
        return self._execute_command(*args, **options)
               ~~~~~~~~~~~~~~~~~~~~~^^^^^^^^^^^^^^^^^^
      File "/Users/bibektimilsina/Library/Caches/pypoetry/virtualenvs/backend-yJOuBi-v-py3.13/lib/python3.13/site-packages/redis/client.py", line 565, in _execute_command
        conn = self.connection or pool.get_connection(command_name, **options)
                                  ~~~~~~~~~~~~~~~~~~~^^^^^^^^^^^^^^^^^^^^^^^^^
      File "/Users/bibektimilsina/Library/Caches/pypoetry/virtualenvs/backend-yJOuBi-v-py3.13/lib/python3.13/site-packages/redis/connection.py", line 1422, in get_connection
        connection.connect()
        ~~~~~~~~~~~~~~~~~~^^
      File "/Users/bibektimilsina/Library/Caches/pypoetry/virtualenvs/backend-yJOuBi-v-py3.13/lib/python3.13/site-packages/redis/connection.py", line 363, in connect
        raise ConnectionError(self._error_message(e))
    redis.exceptions.ConnectionError: Error 61 connecting to localhost:6379. Connection refused.
    
    The above exception was the direct cause of the following exception:
    
    Traceback (most recent call last):
      File "/opt/homebrew/Cellar/python@3.13/3.13.0_1/Frameworks/Python.framework/Versions/3.13/lib/python3.13/concurrent/futures/thread.py", line 58, in run
        result = self.fn(*self.args, **self.kwargs)
      File "/Users/bibektimilsina/Library/Caches/pypoetry/virtualenvs/backend-yJOuBi-v-py3.13/lib/python3.13/site-packages/flower/inspector.py", line 37, in _inspect
        getattr(inspect, method)()
        ~~~~~~~~~~~~~~~~~~~~~~~~^^
      File "/Users/bibektimilsina/Library/Caches/pypoetry/virtualenvs/backend-yJOuBi-v-py3.13/lib/python3.13/site-packages/celery/app/control.py", line 177, in reserved
        return self._request('reserved')
               ~~~~~~~~~~~~~^^^^^^^^^^^^
      File "/Users/bibektimilsina/Library/Caches/pypoetry/virtualenvs/backend-yJOuBi-v-py3.13/lib/python3.13/site-packages/celery/app/control.py", line 106, in _request
        return self._prepare(self.app.control.broadcast(
                             ~~~~~~~~~~~~~~~~~~~~~~~~~~^
            command,
            ^^^^^^^^
        ...<6 lines>...
            pattern=self.pattern, matcher=self.matcher,
            ^^^^^^^^^^^^^^^^^^^^^^^^^^^^^^^^^^^^^^^^^^^
        ))
        ^
      File "/Users/bibektimilsina/Library/Caches/pypoetry/virtualenvs/backend-yJOuBi-v-py3.13/lib/python3.13/site-packages/celery/app/control.py", line 776, in broadcast
        return self.mailbox(conn)._broadcast(
               ~~~~~~~~~~~~~~~~~~~~~~~~~~~~~^
            command, arguments, destination, reply, timeout,
            ^^^^^^^^^^^^^^^^^^^^^^^^^^^^^^^^^^^^^^^^^^^^^^^^
            limit, callback, channel=channel,
            ^^^^^^^^^^^^^^^^^^^^^^^^^^^^^^^^^
        )
        ^
      File "/Users/bibektimilsina/Library/Caches/pypoetry/virtualenvs/backend-yJOuBi-v-py3.13/lib/python3.13/site-packages/kombu/pidbox.py", line 330, in _broadcast
        chan = channel or self.connection.default_channel
                          ^^^^^^^^^^^^^^^^^^^^^^^^^^^^^^^
      File "/Users/bibektimilsina/Library/Caches/pypoetry/virtualenvs/backend-yJOuBi-v-py3.13/lib/python3.13/site-packages/kombu/connection.py", line 953, in default_channel
        self._ensure_connection(**conn_opts)
        ~~~~~~~~~~~~~~~~~~~~~~~^^^^^^^^^^^^^
      File "/Users/bibektimilsina/Library/Caches/pypoetry/virtualenvs/backend-yJOuBi-v-py3.13/lib/python3.13/site-packages/kombu/connection.py", line 458, in _ensure_connection
        with ctx():
             ~~~^^
      File "/opt/homebrew/Cellar/python@3.13/3.13.0_1/Frameworks/Python.framework/Versions/3.13/lib/python3.13/contextlib.py", line 162, in __exit__
        self.gen.throw(value)
        ~~~~~~~~~~~~~~^^^^^^^
      File "/Users/bibektimilsina/Library/Caches/pypoetry/virtualenvs/backend-yJOuBi-v-py3.13/lib/python3.13/site-packages/kombu/connection.py", line 476, in _reraise_as_library_errors
        raise ConnectionError(str(exc)) from exc
    kombu.exceptions.OperationalError: Error 61 connecting to localhost:6379. Connection refused.
[E 241119 13:23:20 base_events:1858] Future exception was never retrieved
    future: <Future finished exception=OperationalError('Error 61 connecting to localhost:6379. Connection refused.')>
    Traceback (most recent call last):
      File "/Users/bibektimilsina/Library/Caches/pypoetry/virtualenvs/backend-yJOuBi-v-py3.13/lib/python3.13/site-packages/kombu/transport/virtual/base.py", line 951, in create_channel
        return self._avail_channels.pop()
               ~~~~~~~~~~~~~~~~~~~~~~~~^^
    IndexError: pop from empty list
    
    During handling of the above exception, another exception occurred:
    
    Traceback (most recent call last):
      File "/Users/bibektimilsina/Library/Caches/pypoetry/virtualenvs/backend-yJOuBi-v-py3.13/lib/python3.13/site-packages/redis/connection.py", line 357, in connect
        sock = self.retry.call_with_retry(
            lambda: self._connect(), lambda error: self.disconnect(error)
        )
      File "/Users/bibektimilsina/Library/Caches/pypoetry/virtualenvs/backend-yJOuBi-v-py3.13/lib/python3.13/site-packages/redis/retry.py", line 62, in call_with_retry
        return do()
      File "/Users/bibektimilsina/Library/Caches/pypoetry/virtualenvs/backend-yJOuBi-v-py3.13/lib/python3.13/site-packages/redis/connection.py", line 358, in <lambda>
        lambda: self._connect(), lambda error: self.disconnect(error)
                ~~~~~~~~~~~~~^^
      File "/Users/bibektimilsina/Library/Caches/pypoetry/virtualenvs/backend-yJOuBi-v-py3.13/lib/python3.13/site-packages/redis/connection.py", line 730, in _connect
        raise err
      File "/Users/bibektimilsina/Library/Caches/pypoetry/virtualenvs/backend-yJOuBi-v-py3.13/lib/python3.13/site-packages/redis/connection.py", line 718, in _connect
        sock.connect(socket_address)
        ~~~~~~~~~~~~^^^^^^^^^^^^^^^^
    ConnectionRefusedError: [Errno 61] Connection refused
    
    During handling of the above exception, another exception occurred:
    
    Traceback (most recent call last):
      File "/Users/bibektimilsina/Library/Caches/pypoetry/virtualenvs/backend-yJOuBi-v-py3.13/lib/python3.13/site-packages/kombu/connection.py", line 472, in _reraise_as_library_errors
        yield
      File "/Users/bibektimilsina/Library/Caches/pypoetry/virtualenvs/backend-yJOuBi-v-py3.13/lib/python3.13/site-packages/kombu/connection.py", line 459, in _ensure_connection
        return retry_over_time(
            self._connection_factory, self.recoverable_connection_errors,
        ...<2 lines>...
            callback, timeout=timeout
        )
      File "/Users/bibektimilsina/Library/Caches/pypoetry/virtualenvs/backend-yJOuBi-v-py3.13/lib/python3.13/site-packages/kombu/utils/functional.py", line 318, in retry_over_time
        return fun(*args, **kwargs)
      File "/Users/bibektimilsina/Library/Caches/pypoetry/virtualenvs/backend-yJOuBi-v-py3.13/lib/python3.13/site-packages/kombu/connection.py", line 934, in _connection_factory
        self._connection = self._establish_connection()
                           ~~~~~~~~~~~~~~~~~~~~~~~~~~^^
      File "/Users/bibektimilsina/Library/Caches/pypoetry/virtualenvs/backend-yJOuBi-v-py3.13/lib/python3.13/site-packages/kombu/connection.py", line 860, in _establish_connection
        conn = self.transport.establish_connection()
      File "/Users/bibektimilsina/Library/Caches/pypoetry/virtualenvs/backend-yJOuBi-v-py3.13/lib/python3.13/site-packages/kombu/transport/virtual/base.py", line 975, in establish_connection
        self._avail_channels.append(self.create_channel(self))
                                    ~~~~~~~~~~~~~~~~~~~^^^^^^
      File "/Users/bibektimilsina/Library/Caches/pypoetry/virtualenvs/backend-yJOuBi-v-py3.13/lib/python3.13/site-packages/kombu/transport/virtual/base.py", line 953, in create_channel
        channel = self.Channel(connection)
      File "/Users/bibektimilsina/Library/Caches/pypoetry/virtualenvs/backend-yJOuBi-v-py3.13/lib/python3.13/site-packages/kombu/transport/redis.py", line 744, in __init__
        self.client.ping()
        ~~~~~~~~~~~~~~~~^^
      File "/Users/bibektimilsina/Library/Caches/pypoetry/virtualenvs/backend-yJOuBi-v-py3.13/lib/python3.13/site-packages/redis/commands/core.py", line 1212, in ping
        return self.execute_command("PING", **kwargs)
               ~~~~~~~~~~~~~~~~~~~~^^^^^^^^^^^^^^^^^^
      File "/Users/bibektimilsina/Library/Caches/pypoetry/virtualenvs/backend-yJOuBi-v-py3.13/lib/python3.13/site-packages/redis/client.py", line 559, in execute_command
        return self._execute_command(*args, **options)
               ~~~~~~~~~~~~~~~~~~~~~^^^^^^^^^^^^^^^^^^
      File "/Users/bibektimilsina/Library/Caches/pypoetry/virtualenvs/backend-yJOuBi-v-py3.13/lib/python3.13/site-packages/redis/client.py", line 565, in _execute_command
        conn = self.connection or pool.get_connection(command_name, **options)
                                  ~~~~~~~~~~~~~~~~~~~^^^^^^^^^^^^^^^^^^^^^^^^^
      File "/Users/bibektimilsina/Library/Caches/pypoetry/virtualenvs/backend-yJOuBi-v-py3.13/lib/python3.13/site-packages/redis/connection.py", line 1422, in get_connection
        connection.connect()
        ~~~~~~~~~~~~~~~~~~^^
      File "/Users/bibektimilsina/Library/Caches/pypoetry/virtualenvs/backend-yJOuBi-v-py3.13/lib/python3.13/site-packages/redis/connection.py", line 363, in connect
        raise ConnectionError(self._error_message(e))
    redis.exceptions.ConnectionError: Error 61 connecting to localhost:6379. Connection refused.
    
    The above exception was the direct cause of the following exception:
    
    Traceback (most recent call last):
      File "/opt/homebrew/Cellar/python@3.13/3.13.0_1/Frameworks/Python.framework/Versions/3.13/lib/python3.13/concurrent/futures/thread.py", line 58, in run
        result = self.fn(*self.args, **self.kwargs)
      File "/Users/bibektimilsina/Library/Caches/pypoetry/virtualenvs/backend-yJOuBi-v-py3.13/lib/python3.13/site-packages/flower/inspector.py", line 37, in _inspect
        getattr(inspect, method)()
        ~~~~~~~~~~~~~~~~~~~~~~~~^^
      File "/Users/bibektimilsina/Library/Caches/pypoetry/virtualenvs/backend-yJOuBi-v-py3.13/lib/python3.13/site-packages/celery/app/control.py", line 386, in conf
        return self._request('conf', with_defaults=with_defaults)
               ~~~~~~~~~~~~~^^^^^^^^^^^^^^^^^^^^^^^^^^^^^^^^^^^^^
      File "/Users/bibektimilsina/Library/Caches/pypoetry/virtualenvs/backend-yJOuBi-v-py3.13/lib/python3.13/site-packages/celery/app/control.py", line 106, in _request
        return self._prepare(self.app.control.broadcast(
                             ~~~~~~~~~~~~~~~~~~~~~~~~~~^
            command,
            ^^^^^^^^
        ...<6 lines>...
            pattern=self.pattern, matcher=self.matcher,
            ^^^^^^^^^^^^^^^^^^^^^^^^^^^^^^^^^^^^^^^^^^^
        ))
        ^
      File "/Users/bibektimilsina/Library/Caches/pypoetry/virtualenvs/backend-yJOuBi-v-py3.13/lib/python3.13/site-packages/celery/app/control.py", line 776, in broadcast
        return self.mailbox(conn)._broadcast(
               ~~~~~~~~~~~~~~~~~~~~~~~~~~~~~^
            command, arguments, destination, reply, timeout,
            ^^^^^^^^^^^^^^^^^^^^^^^^^^^^^^^^^^^^^^^^^^^^^^^^
            limit, callback, channel=channel,
            ^^^^^^^^^^^^^^^^^^^^^^^^^^^^^^^^^
        )
        ^
      File "/Users/bibektimilsina/Library/Caches/pypoetry/virtualenvs/backend-yJOuBi-v-py3.13/lib/python3.13/site-packages/kombu/pidbox.py", line 330, in _broadcast
        chan = channel or self.connection.default_channel
                          ^^^^^^^^^^^^^^^^^^^^^^^^^^^^^^^
      File "/Users/bibektimilsina/Library/Caches/pypoetry/virtualenvs/backend-yJOuBi-v-py3.13/lib/python3.13/site-packages/kombu/connection.py", line 953, in default_channel
        self._ensure_connection(**conn_opts)
        ~~~~~~~~~~~~~~~~~~~~~~~^^^^^^^^^^^^^
      File "/Users/bibektimilsina/Library/Caches/pypoetry/virtualenvs/backend-yJOuBi-v-py3.13/lib/python3.13/site-packages/kombu/connection.py", line 458, in _ensure_connection
        with ctx():
             ~~~^^
      File "/opt/homebrew/Cellar/python@3.13/3.13.0_1/Frameworks/Python.framework/Versions/3.13/lib/python3.13/contextlib.py", line 162, in __exit__
        self.gen.throw(value)
        ~~~~~~~~~~~~~~^^^^^^^
      File "/Users/bibektimilsina/Library/Caches/pypoetry/virtualenvs/backend-yJOuBi-v-py3.13/lib/python3.13/site-packages/kombu/connection.py", line 476, in _reraise_as_library_errors
        raise ConnectionError(str(exc)) from exc
    kombu.exceptions.OperationalError: Error 61 connecting to localhost:6379. Connection refused.
[E 241119 13:23:20 base_events:1858] Future exception was never retrieved
    future: <Future finished exception=OperationalError('Error 61 connecting to localhost:6379. Connection refused.')>
    Traceback (most recent call last):
      File "/Users/bibektimilsina/Library/Caches/pypoetry/virtualenvs/backend-yJOuBi-v-py3.13/lib/python3.13/site-packages/kombu/transport/virtual/base.py", line 951, in create_channel
        return self._avail_channels.pop()
               ~~~~~~~~~~~~~~~~~~~~~~~~^^
    IndexError: pop from empty list
    
    During handling of the above exception, another exception occurred:
    
    Traceback (most recent call last):
      File "/Users/bibektimilsina/Library/Caches/pypoetry/virtualenvs/backend-yJOuBi-v-py3.13/lib/python3.13/site-packages/redis/connection.py", line 357, in connect
        sock = self.retry.call_with_retry(
            lambda: self._connect(), lambda error: self.disconnect(error)
        )
      File "/Users/bibektimilsina/Library/Caches/pypoetry/virtualenvs/backend-yJOuBi-v-py3.13/lib/python3.13/site-packages/redis/retry.py", line 62, in call_with_retry
        return do()
      File "/Users/bibektimilsina/Library/Caches/pypoetry/virtualenvs/backend-yJOuBi-v-py3.13/lib/python3.13/site-packages/redis/connection.py", line 358, in <lambda>
        lambda: self._connect(), lambda error: self.disconnect(error)
                ~~~~~~~~~~~~~^^
      File "/Users/bibektimilsina/Library/Caches/pypoetry/virtualenvs/backend-yJOuBi-v-py3.13/lib/python3.13/site-packages/redis/connection.py", line 730, in _connect
        raise err
      File "/Users/bibektimilsina/Library/Caches/pypoetry/virtualenvs/backend-yJOuBi-v-py3.13/lib/python3.13/site-packages/redis/connection.py", line 718, in _connect
        sock.connect(socket_address)
        ~~~~~~~~~~~~^^^^^^^^^^^^^^^^
    ConnectionRefusedError: [Errno 61] Connection refused
    
    During handling of the above exception, another exception occurred:
    
    Traceback (most recent call last):
      File "/Users/bibektimilsina/Library/Caches/pypoetry/virtualenvs/backend-yJOuBi-v-py3.13/lib/python3.13/site-packages/kombu/connection.py", line 472, in _reraise_as_library_errors
        yield
      File "/Users/bibektimilsina/Library/Caches/pypoetry/virtualenvs/backend-yJOuBi-v-py3.13/lib/python3.13/site-packages/kombu/connection.py", line 459, in _ensure_connection
        return retry_over_time(
            self._connection_factory, self.recoverable_connection_errors,
        ...<2 lines>...
            callback, timeout=timeout
        )
      File "/Users/bibektimilsina/Library/Caches/pypoetry/virtualenvs/backend-yJOuBi-v-py3.13/lib/python3.13/site-packages/kombu/utils/functional.py", line 318, in retry_over_time
        return fun(*args, **kwargs)
      File "/Users/bibektimilsina/Library/Caches/pypoetry/virtualenvs/backend-yJOuBi-v-py3.13/lib/python3.13/site-packages/kombu/connection.py", line 934, in _connection_factory
        self._connection = self._establish_connection()
                           ~~~~~~~~~~~~~~~~~~~~~~~~~~^^
      File "/Users/bibektimilsina/Library/Caches/pypoetry/virtualenvs/backend-yJOuBi-v-py3.13/lib/python3.13/site-packages/kombu/connection.py", line 860, in _establish_connection
        conn = self.transport.establish_connection()
      File "/Users/bibektimilsina/Library/Caches/pypoetry/virtualenvs/backend-yJOuBi-v-py3.13/lib/python3.13/site-packages/kombu/transport/virtual/base.py", line 975, in establish_connection
        self._avail_channels.append(self.create_channel(self))
                                    ~~~~~~~~~~~~~~~~~~~^^^^^^
      File "/Users/bibektimilsina/Library/Caches/pypoetry/virtualenvs/backend-yJOuBi-v-py3.13/lib/python3.13/site-packages/kombu/transport/virtual/base.py", line 953, in create_channel
        channel = self.Channel(connection)
      File "/Users/bibektimilsina/Library/Caches/pypoetry/virtualenvs/backend-yJOuBi-v-py3.13/lib/python3.13/site-packages/kombu/transport/redis.py", line 744, in __init__
        self.client.ping()
        ~~~~~~~~~~~~~~~~^^
      File "/Users/bibektimilsina/Library/Caches/pypoetry/virtualenvs/backend-yJOuBi-v-py3.13/lib/python3.13/site-packages/redis/commands/core.py", line 1212, in ping
        return self.execute_command("PING", **kwargs)
               ~~~~~~~~~~~~~~~~~~~~^^^^^^^^^^^^^^^^^^
      File "/Users/bibektimilsina/Library/Caches/pypoetry/virtualenvs/backend-yJOuBi-v-py3.13/lib/python3.13/site-packages/redis/client.py", line 559, in execute_command
        return self._execute_command(*args, **options)
               ~~~~~~~~~~~~~~~~~~~~~^^^^^^^^^^^^^^^^^^
      File "/Users/bibektimilsina/Library/Caches/pypoetry/virtualenvs/backend-yJOuBi-v-py3.13/lib/python3.13/site-packages/redis/client.py", line 565, in _execute_command
        conn = self.connection or pool.get_connection(command_name, **options)
                                  ~~~~~~~~~~~~~~~~~~~^^^^^^^^^^^^^^^^^^^^^^^^^
      File "/Users/bibektimilsina/Library/Caches/pypoetry/virtualenvs/backend-yJOuBi-v-py3.13/lib/python3.13/site-packages/redis/connection.py", line 1422, in get_connection
        connection.connect()
        ~~~~~~~~~~~~~~~~~~^^
      File "/Users/bibektimilsina/Library/Caches/pypoetry/virtualenvs/backend-yJOuBi-v-py3.13/lib/python3.13/site-packages/redis/connection.py", line 363, in connect
        raise ConnectionError(self._error_message(e))
    redis.exceptions.ConnectionError: Error 61 connecting to localhost:6379. Connection refused.
    
    The above exception was the direct cause of the following exception:
    
    Traceback (most recent call last):
      File "/opt/homebrew/Cellar/python@3.13/3.13.0_1/Frameworks/Python.framework/Versions/3.13/lib/python3.13/concurrent/futures/thread.py", line 58, in run
        result = self.fn(*self.args, **self.kwargs)
      File "/Users/bibektimilsina/Library/Caches/pypoetry/virtualenvs/backend-yJOuBi-v-py3.13/lib/python3.13/site-packages/flower/inspector.py", line 39, in _inspect
        else getattr(inspect, method)(safe=True)
             ~~~~~~~~~~~~~~~~~~~~~~~~^^^^^^^^^^^
      File "/Users/bibektimilsina/Library/Caches/pypoetry/virtualenvs/backend-yJOuBi-v-py3.13/lib/python3.13/site-packages/celery/app/control.py", line 149, in active
        return self._request('active', safe=safe)
               ~~~~~~~~~~~~~^^^^^^^^^^^^^^^^^^^^^
      File "/Users/bibektimilsina/Library/Caches/pypoetry/virtualenvs/backend-yJOuBi-v-py3.13/lib/python3.13/site-packages/celery/app/control.py", line 106, in _request
        return self._prepare(self.app.control.broadcast(
                             ~~~~~~~~~~~~~~~~~~~~~~~~~~^
            command,
            ^^^^^^^^
        ...<6 lines>...
            pattern=self.pattern, matcher=self.matcher,
            ^^^^^^^^^^^^^^^^^^^^^^^^^^^^^^^^^^^^^^^^^^^
        ))
        ^
      File "/Users/bibektimilsina/Library/Caches/pypoetry/virtualenvs/backend-yJOuBi-v-py3.13/lib/python3.13/site-packages/celery/app/control.py", line 776, in broadcast
        return self.mailbox(conn)._broadcast(
               ~~~~~~~~~~~~~~~~~~~~~~~~~~~~~^
            command, arguments, destination, reply, timeout,
            ^^^^^^^^^^^^^^^^^^^^^^^^^^^^^^^^^^^^^^^^^^^^^^^^
            limit, callback, channel=channel,
            ^^^^^^^^^^^^^^^^^^^^^^^^^^^^^^^^^
        )
        ^
      File "/Users/bibektimilsina/Library/Caches/pypoetry/virtualenvs/backend-yJOuBi-v-py3.13/lib/python3.13/site-packages/kombu/pidbox.py", line 330, in _broadcast
        chan = channel or self.connection.default_channel
                          ^^^^^^^^^^^^^^^^^^^^^^^^^^^^^^^
      File "/Users/bibektimilsina/Library/Caches/pypoetry/virtualenvs/backend-yJOuBi-v-py3.13/lib/python3.13/site-packages/kombu/connection.py", line 953, in default_channel
        self._ensure_connection(**conn_opts)
        ~~~~~~~~~~~~~~~~~~~~~~~^^^^^^^^^^^^^
      File "/Users/bibektimilsina/Library/Caches/pypoetry/virtualenvs/backend-yJOuBi-v-py3.13/lib/python3.13/site-packages/kombu/connection.py", line 458, in _ensure_connection
        with ctx():
             ~~~^^
      File "/opt/homebrew/Cellar/python@3.13/3.13.0_1/Frameworks/Python.framework/Versions/3.13/lib/python3.13/contextlib.py", line 162, in __exit__
        self.gen.throw(value)
        ~~~~~~~~~~~~~~^^^^^^^
      File "/Users/bibektimilsina/Library/Caches/pypoetry/virtualenvs/backend-yJOuBi-v-py3.13/lib/python3.13/site-packages/kombu/connection.py", line 476, in _reraise_as_library_errors
        raise ConnectionError(str(exc)) from exc
    kombu.exceptions.OperationalError: Error 61 connecting to localhost:6379. Connection refused.
[I 241119 13:23:23 command:28] 15 detected, shutting down
